2025-04-08 16:42:39 - webdriver - ERROR - Ошибка при инициализации WebDriver: File is not a zip file
Traceback (most recent call last):
  File "C:\Users\priva\Desktop\Zapros2\main.py", line 28, in init_driver
    service = Service(ChromeDriverManager().install())
                      ^^^^^^^^^^^^^^^^^^^^^^^^^^^^^^^
  File "C:\Users\priva\Desktop\Zapros2\.venv1\Lib\site-packages\webdriver_manager\chrome.py", line 40, in install
    driver_path = self._get_driver_binary_path(self.driver)
                  ^^^^^^^^^^^^^^^^^^^^^^^^^^^^^^^^^^^^^^^^^
  File "C:\Users\priva\Desktop\Zapros2\.venv1\Lib\site-packages\webdriver_manager\core\manager.py", line 41, in _get_driver_binary_path
    binary_path = self._cache_manager.save_file_to_cache(driver, file)
                  ^^^^^^^^^^^^^^^^^^^^^^^^^^^^^^^^^^^^^^^^^^^^^^^^^^^^
  File "C:\Users\priva\Desktop\Zapros2\.venv1\Lib\site-packages\webdriver_manager\core\driver_cache.py", line 54, in save_file_to_cache
    files = self.unpack_archive(archive, path)
            ^^^^^^^^^^^^^^^^^^^^^^^^^^^^^^^^^^
  File "C:\Users\priva\Desktop\Zapros2\.venv1\Lib\site-packages\webdriver_manager\core\driver_cache.py", line 49, in unpack_archive
    return self._file_manager.unpack_archive(archive, path)
           ^^^^^^^^^^^^^^^^^^^^^^^^^^^^^^^^^^^^^^^^^^^^^^^^
  File "C:\Users\priva\Desktop\Zapros2\.venv1\Lib\site-packages\webdriver_manager\core\file_manager.py", line 57, in unpack_archive
    return self.__extract_zip(archive_file, target_dir)
           ^^^^^^^^^^^^^^^^^^^^^^^^^^^^^^^^^^^^^^^^^^^^
  File "C:\Users\priva\Desktop\Zapros2\.venv1\Lib\site-packages\webdriver_manager\core\file_manager.py", line 63, in __extract_zip
    archive = zip_class(archive_file.file_path)
              ^^^^^^^^^^^^^^^^^^^^^^^^^^^^^^^^^
  File "C:\Users\priva\AppData\Local\Programs\Python\Python311\Lib\zipfile.py", line 1312, in __init__
    self._RealGetContents()
  File "C:\Users\priva\AppData\Local\Programs\Python\Python311\Lib\zipfile.py", line 1379, in _RealGetContents
    raise BadZipFile("File is not a zip file")
zipfile.BadZipFile: File is not a zip file
2025-04-08 16:42:39 - webdriver - ERROR - Ошибка при инициализации WebDriver: File is not a zip file
Traceback (most recent call last):
  File "C:\Users\priva\Desktop\Zapros2\main.py", line 28, in init_driver
    service = Service(ChromeDriverManager().install())
                      ^^^^^^^^^^^^^^^^^^^^^^^^^^^^^^^
  File "C:\Users\priva\Desktop\Zapros2\.venv1\Lib\site-packages\webdriver_manager\chrome.py", line 40, in install
    driver_path = self._get_driver_binary_path(self.driver)
                  ^^^^^^^^^^^^^^^^^^^^^^^^^^^^^^^^^^^^^^^^^
  File "C:\Users\priva\Desktop\Zapros2\.venv1\Lib\site-packages\webdriver_manager\core\manager.py", line 41, in _get_driver_binary_path
    binary_path = self._cache_manager.save_file_to_cache(driver, file)
                  ^^^^^^^^^^^^^^^^^^^^^^^^^^^^^^^^^^^^^^^^^^^^^^^^^^^^
  File "C:\Users\priva\Desktop\Zapros2\.venv1\Lib\site-packages\webdriver_manager\core\driver_cache.py", line 54, in save_file_to_cache
    files = self.unpack_archive(archive, path)
            ^^^^^^^^^^^^^^^^^^^^^^^^^^^^^^^^^^
  File "C:\Users\priva\Desktop\Zapros2\.venv1\Lib\site-packages\webdriver_manager\core\driver_cache.py", line 49, in unpack_archive
    return self._file_manager.unpack_archive(archive, path)
           ^^^^^^^^^^^^^^^^^^^^^^^^^^^^^^^^^^^^^^^^^^^^^^^^
  File "C:\Users\priva\Desktop\Zapros2\.venv1\Lib\site-packages\webdriver_manager\core\file_manager.py", line 57, in unpack_archive
    return self.__extract_zip(archive_file, target_dir)
           ^^^^^^^^^^^^^^^^^^^^^^^^^^^^^^^^^^^^^^^^^^^^
  File "C:\Users\priva\Desktop\Zapros2\.venv1\Lib\site-packages\webdriver_manager\core\file_manager.py", line 63, in __extract_zip
    archive = zip_class(archive_file.file_path)
              ^^^^^^^^^^^^^^^^^^^^^^^^^^^^^^^^^
  File "C:\Users\priva\AppData\Local\Programs\Python\Python311\Lib\zipfile.py", line 1312, in __init__
    self._RealGetContents()
  File "C:\Users\priva\AppData\Local\Programs\Python\Python311\Lib\zipfile.py", line 1379, in _RealGetContents
    raise BadZipFile("File is not a zip file")
zipfile.BadZipFile: File is not a zip file
2025-04-08 16:42:39 - webdriver - ERROR - Ошибка при инициализации WebDriver: [WinError 183] Невозможно создать файл, так как он уже существует: 'C:\\Users\\priva\\.wdm\\drivers\\chromedriver\\win64\\135.0.7049.42\\chromedriver-win32'
Traceback (most recent call last):
  File "C:\Users\priva\Desktop\Zapros2\main.py", line 28, in init_driver
    service = Service(ChromeDriverManager().install())
                      ^^^^^^^^^^^^^^^^^^^^^^^^^^^^^^^
  File "C:\Users\priva\Desktop\Zapros2\.venv1\Lib\site-packages\webdriver_manager\chrome.py", line 40, in install
    driver_path = self._get_driver_binary_path(self.driver)
                  ^^^^^^^^^^^^^^^^^^^^^^^^^^^^^^^^^^^^^^^^^
  File "C:\Users\priva\Desktop\Zapros2\.venv1\Lib\site-packages\webdriver_manager\core\manager.py", line 41, in _get_driver_binary_path
    binary_path = self._cache_manager.save_file_to_cache(driver, file)
                  ^^^^^^^^^^^^^^^^^^^^^^^^^^^^^^^^^^^^^^^^^^^^^^^^^^^^
  File "C:\Users\priva\Desktop\Zapros2\.venv1\Lib\site-packages\webdriver_manager\core\driver_cache.py", line 54, in save_file_to_cache
    files = self.unpack_archive(archive, path)
            ^^^^^^^^^^^^^^^^^^^^^^^^^^^^^^^^^^
  File "C:\Users\priva\Desktop\Zapros2\.venv1\Lib\site-packages\webdriver_manager\core\driver_cache.py", line 49, in unpack_archive
    return self._file_manager.unpack_archive(archive, path)
           ^^^^^^^^^^^^^^^^^^^^^^^^^^^^^^^^^^^^^^^^^^^^^^^^
  File "C:\Users\priva\Desktop\Zapros2\.venv1\Lib\site-packages\webdriver_manager\core\file_manager.py", line 57, in unpack_archive
    return self.__extract_zip(archive_file, target_dir)
           ^^^^^^^^^^^^^^^^^^^^^^^^^^^^^^^^^^^^^^^^^^^^
  File "C:\Users\priva\Desktop\Zapros2\.venv1\Lib\site-packages\webdriver_manager\core\file_manager.py", line 71, in __extract_zip
    raise e
  File "C:\Users\priva\Desktop\Zapros2\.venv1\Lib\site-packages\webdriver_manager\core\file_manager.py", line 65, in __extract_zip
    archive.extractall(to_directory)
  File "C:\Users\priva\AppData\Local\Programs\Python\Python311\Lib\zipfile.py", line 1701, in extractall
    self._extract_member(zipinfo, path, pwd)
  File "C:\Users\priva\AppData\Local\Programs\Python\Python311\Lib\zipfile.py", line 1747, in _extract_member
    os.makedirs(upperdirs)
  File "<frozen os>", line 225, in makedirs
FileExistsError: [WinError 183] Невозможно создать файл, так как он уже существует: 'C:\\Users\\priva\\.wdm\\drivers\\chromedriver\\win64\\135.0.7049.42\\chromedriver-win32'
2025-04-08 16:42:39 - webdriver - ERROR - Ошибка при инициализации WebDriver: Expecting value: line 1 column 1 (char 0)
Traceback (most recent call last):
  File "C:\Users\priva\Desktop\Zapros2\main.py", line 28, in init_driver
    service = Service(ChromeDriverManager().install())
                      ^^^^^^^^^^^^^^^^^^^^^^^^^^^^^^^
  File "C:\Users\priva\Desktop\Zapros2\.venv1\Lib\site-packages\webdriver_manager\chrome.py", line 40, in install
    driver_path = self._get_driver_binary_path(self.driver)
                  ^^^^^^^^^^^^^^^^^^^^^^^^^^^^^^^^^^^^^^^^^
  File "C:\Users\priva\Desktop\Zapros2\.venv1\Lib\site-packages\webdriver_manager\core\manager.py", line 41, in _get_driver_binary_path
    binary_path = self._cache_manager.save_file_to_cache(driver, file)
                  ^^^^^^^^^^^^^^^^^^^^^^^^^^^^^^^^^^^^^^^^^^^^^^^^^^^^
  File "C:\Users\priva\Desktop\Zapros2\.venv1\Lib\site-packages\webdriver_manager\core\driver_cache.py", line 57, in save_file_to_cache
    self.__save_metadata(driver, binary_path)
  File "C:\Users\priva\Desktop\Zapros2\.venv1\Lib\site-packages\webdriver_manager\core\driver_cache.py", line 82, in __save_metadata
    metadata = self.load_metadata_content()
               ^^^^^^^^^^^^^^^^^^^^^^^^^^^^
  File "C:\Users\priva\Desktop\Zapros2\.venv1\Lib\site-packages\webdriver_manager\core\driver_cache.py", line 137, in load_metadata_content
    return json.load(outfile)
           ^^^^^^^^^^^^^^^^^^
  File "C:\Users\priva\AppData\Local\Programs\Python\Python311\Lib\json\__init__.py", line 293, in load
    return loads(fp.read(),
           ^^^^^^^^^^^^^^^^
  File "C:\Users\priva\AppData\Local\Programs\Python\Python311\Lib\json\__init__.py", line 346, in loads
    return _default_decoder.decode(s)
           ^^^^^^^^^^^^^^^^^^^^^^^^^^
  File "C:\Users\priva\AppData\Local\Programs\Python\Python311\Lib\json\decoder.py", line 337, in decode
    obj, end = self.raw_decode(s, idx=_w(s, 0).end())
               ^^^^^^^^^^^^^^^^^^^^^^^^^^^^^^^^^^^^^^
  File "C:\Users\priva\AppData\Local\Programs\Python\Python311\Lib\json\decoder.py", line 355, in raw_decode
    raise JSONDecodeError("Expecting value", s, err.value) from None
json.decoder.JSONDecodeError: Expecting value: line 1 column 1 (char 0)
2025-04-08 16:42:39 - webdriver - ERROR - Ошибка при инициализации WebDriver: Expecting value: line 1 column 1 (char 0)
Traceback (most recent call last):
  File "C:\Users\priva\Desktop\Zapros2\main.py", line 28, in init_driver
    service = Service(ChromeDriverManager().install())
                      ^^^^^^^^^^^^^^^^^^^^^^^^^^^^^^^
  File "C:\Users\priva\Desktop\Zapros2\.venv1\Lib\site-packages\webdriver_manager\chrome.py", line 40, in install
    driver_path = self._get_driver_binary_path(self.driver)
                  ^^^^^^^^^^^^^^^^^^^^^^^^^^^^^^^^^^^^^^^^^
  File "C:\Users\priva\Desktop\Zapros2\.venv1\Lib\site-packages\webdriver_manager\core\manager.py", line 41, in _get_driver_binary_path
    binary_path = self._cache_manager.save_file_to_cache(driver, file)
                  ^^^^^^^^^^^^^^^^^^^^^^^^^^^^^^^^^^^^^^^^^^^^^^^^^^^^
  File "C:\Users\priva\Desktop\Zapros2\.venv1\Lib\site-packages\webdriver_manager\core\driver_cache.py", line 57, in save_file_to_cache
    self.__save_metadata(driver, binary_path)
  File "C:\Users\priva\Desktop\Zapros2\.venv1\Lib\site-packages\webdriver_manager\core\driver_cache.py", line 82, in __save_metadata
    metadata = self.load_metadata_content()
               ^^^^^^^^^^^^^^^^^^^^^^^^^^^^
  File "C:\Users\priva\Desktop\Zapros2\.venv1\Lib\site-packages\webdriver_manager\core\driver_cache.py", line 137, in load_metadata_content
    return json.load(outfile)
           ^^^^^^^^^^^^^^^^^^
  File "C:\Users\priva\AppData\Local\Programs\Python\Python311\Lib\json\__init__.py", line 293, in load
    return loads(fp.read(),
           ^^^^^^^^^^^^^^^^
  File "C:\Users\priva\AppData\Local\Programs\Python\Python311\Lib\json\__init__.py", line 346, in loads
    return _default_decoder.decode(s)
           ^^^^^^^^^^^^^^^^^^^^^^^^^^
  File "C:\Users\priva\AppData\Local\Programs\Python\Python311\Lib\json\decoder.py", line 337, in decode
    obj, end = self.raw_decode(s, idx=_w(s, 0).end())
               ^^^^^^^^^^^^^^^^^^^^^^^^^^^^^^^^^^^^^^
  File "C:\Users\priva\AppData\Local\Programs\Python\Python311\Lib\json\decoder.py", line 355, in raw_decode
    raise JSONDecodeError("Expecting value", s, err.value) from None
json.decoder.JSONDecodeError: Expecting value: line 1 column 1 (char 0)
2025-04-08 16:42:39 - webdriver - ERROR - Ошибка при инициализации WebDriver: Message: 'chromedriver.exe' executable may have wrong permissions.
Traceback (most recent call last):
  File "C:\Users\priva\Desktop\Zapros2\.venv1\Lib\site-packages\selenium\webdriver\common\service.py", line 219, in _start_process
    self.process = subprocess.Popen(
                   ^^^^^^^^^^^^^^^^^
  File "C:\Users\priva\AppData\Local\Programs\Python\Python311\Lib\subprocess.py", line 1026, in __init__
    self._execute_child(args, executable, preexec_fn, close_fds,
  File "C:\Users\priva\AppData\Local\Programs\Python\Python311\Lib\subprocess.py", line 1538, in _execute_child
    hp, ht, pid, tid = _winapi.CreateProcess(executable, args,
                       ^^^^^^^^^^^^^^^^^^^^^^^^^^^^^^^^^^^^^^^
PermissionError: [WinError 32] Процесс не может получить доступ к файлу, так как этот файл занят другим процессом

The above exception was the direct cause of the following exception:

Traceback (most recent call last):
  File "C:\Users\priva\Desktop\Zapros2\main.py", line 29, in init_driver
    driver = webdriver.Chrome(service=service, options=options)
             ^^^^^^^^^^^^^^^^^^^^^^^^^^^^^^^^^^^^^^^^^^^^^^^^^^
  File "C:\Users\priva\Desktop\Zapros2\.venv1\Lib\site-packages\selenium\webdriver\chrome\webdriver.py", line 45, in __init__
    super().__init__(
  File "C:\Users\priva\Desktop\Zapros2\.venv1\Lib\site-packages\selenium\webdriver\chromium\webdriver.py", line 55, in __init__
    self.service.start()
  File "C:\Users\priva\Desktop\Zapros2\.venv1\Lib\site-packages\selenium\webdriver\common\service.py", line 109, in start
    self._start_process(self._path)
  File "C:\Users\priva\Desktop\Zapros2\.venv1\Lib\site-packages\selenium\webdriver\common\service.py", line 243, in _start_process
    raise WebDriverException(
selenium.common.exceptions.WebDriverException: Message: 'chromedriver.exe' executable may have wrong permissions.

2025-04-08 16:42:39 - webdriver - ERROR - Ошибка при инициализации WebDriver: Expecting value: line 1 column 1 (char 0)
Traceback (most recent call last):
  File "C:\Users\priva\Desktop\Zapros2\main.py", line 28, in init_driver
    service = Service(ChromeDriverManager().install())
                      ^^^^^^^^^^^^^^^^^^^^^^^^^^^^^^^
  File "C:\Users\priva\Desktop\Zapros2\.venv1\Lib\site-packages\webdriver_manager\chrome.py", line 40, in install
    driver_path = self._get_driver_binary_path(self.driver)
                  ^^^^^^^^^^^^^^^^^^^^^^^^^^^^^^^^^^^^^^^^^
  File "C:\Users\priva\Desktop\Zapros2\.venv1\Lib\site-packages\webdriver_manager\core\manager.py", line 41, in _get_driver_binary_path
    binary_path = self._cache_manager.save_file_to_cache(driver, file)
                  ^^^^^^^^^^^^^^^^^^^^^^^^^^^^^^^^^^^^^^^^^^^^^^^^^^^^
  File "C:\Users\priva\Desktop\Zapros2\.venv1\Lib\site-packages\webdriver_manager\core\driver_cache.py", line 57, in save_file_to_cache
    self.__save_metadata(driver, binary_path)
  File "C:\Users\priva\Desktop\Zapros2\.venv1\Lib\site-packages\webdriver_manager\core\driver_cache.py", line 82, in __save_metadata
    metadata = self.load_metadata_content()
               ^^^^^^^^^^^^^^^^^^^^^^^^^^^^
  File "C:\Users\priva\Desktop\Zapros2\.venv1\Lib\site-packages\webdriver_manager\core\driver_cache.py", line 137, in load_metadata_content
    return json.load(outfile)
           ^^^^^^^^^^^^^^^^^^
  File "C:\Users\priva\AppData\Local\Programs\Python\Python311\Lib\json\__init__.py", line 293, in load
    return loads(fp.read(),
           ^^^^^^^^^^^^^^^^
  File "C:\Users\priva\AppData\Local\Programs\Python\Python311\Lib\json\__init__.py", line 346, in loads
    return _default_decoder.decode(s)
           ^^^^^^^^^^^^^^^^^^^^^^^^^^
  File "C:\Users\priva\AppData\Local\Programs\Python\Python311\Lib\json\decoder.py", line 337, in decode
    obj, end = self.raw_decode(s, idx=_w(s, 0).end())
               ^^^^^^^^^^^^^^^^^^^^^^^^^^^^^^^^^^^^^^
  File "C:\Users\priva\AppData\Local\Programs\Python\Python311\Lib\json\decoder.py", line 355, in raw_decode
    raise JSONDecodeError("Expecting value", s, err.value) from None
json.decoder.JSONDecodeError: Expecting value: line 1 column 1 (char 0)
2025-04-08 16:42:39 - webdriver - ERROR - Ошибка при инициализации WebDriver: Expecting value: line 1 column 1 (char 0)
Traceback (most recent call last):
  File "C:\Users\priva\Desktop\Zapros2\main.py", line 28, in init_driver
    service = Service(ChromeDriverManager().install())
                      ^^^^^^^^^^^^^^^^^^^^^^^^^^^^^^^
  File "C:\Users\priva\Desktop\Zapros2\.venv1\Lib\site-packages\webdriver_manager\chrome.py", line 40, in install
    driver_path = self._get_driver_binary_path(self.driver)
                  ^^^^^^^^^^^^^^^^^^^^^^^^^^^^^^^^^^^^^^^^^
  File "C:\Users\priva\Desktop\Zapros2\.venv1\Lib\site-packages\webdriver_manager\core\manager.py", line 41, in _get_driver_binary_path
    binary_path = self._cache_manager.save_file_to_cache(driver, file)
                  ^^^^^^^^^^^^^^^^^^^^^^^^^^^^^^^^^^^^^^^^^^^^^^^^^^^^
  File "C:\Users\priva\Desktop\Zapros2\.venv1\Lib\site-packages\webdriver_manager\core\driver_cache.py", line 57, in save_file_to_cache
    self.__save_metadata(driver, binary_path)
  File "C:\Users\priva\Desktop\Zapros2\.venv1\Lib\site-packages\webdriver_manager\core\driver_cache.py", line 82, in __save_metadata
    metadata = self.load_metadata_content()
               ^^^^^^^^^^^^^^^^^^^^^^^^^^^^
  File "C:\Users\priva\Desktop\Zapros2\.venv1\Lib\site-packages\webdriver_manager\core\driver_cache.py", line 137, in load_metadata_content
    return json.load(outfile)
           ^^^^^^^^^^^^^^^^^^
  File "C:\Users\priva\AppData\Local\Programs\Python\Python311\Lib\json\__init__.py", line 293, in load
    return loads(fp.read(),
           ^^^^^^^^^^^^^^^^
  File "C:\Users\priva\AppData\Local\Programs\Python\Python311\Lib\json\__init__.py", line 346, in loads
    return _default_decoder.decode(s)
           ^^^^^^^^^^^^^^^^^^^^^^^^^^
  File "C:\Users\priva\AppData\Local\Programs\Python\Python311\Lib\json\decoder.py", line 337, in decode
    obj, end = self.raw_decode(s, idx=_w(s, 0).end())
               ^^^^^^^^^^^^^^^^^^^^^^^^^^^^^^^^^^^^^^
  File "C:\Users\priva\AppData\Local\Programs\Python\Python311\Lib\json\decoder.py", line 355, in raw_decode
    raise JSONDecodeError("Expecting value", s, err.value) from None
json.decoder.JSONDecodeError: Expecting value: line 1 column 1 (char 0)
2025-04-08 16:42:39 - webdriver - ERROR - Ошибка при инициализации WebDriver: Expecting value: line 1 column 1 (char 0)
Traceback (most recent call last):
  File "C:\Users\priva\Desktop\Zapros2\main.py", line 28, in init_driver
    service = Service(ChromeDriverManager().install())
                      ^^^^^^^^^^^^^^^^^^^^^^^^^^^^^^^
  File "C:\Users\priva\Desktop\Zapros2\.venv1\Lib\site-packages\webdriver_manager\chrome.py", line 40, in install
    driver_path = self._get_driver_binary_path(self.driver)
                  ^^^^^^^^^^^^^^^^^^^^^^^^^^^^^^^^^^^^^^^^^
  File "C:\Users\priva\Desktop\Zapros2\.venv1\Lib\site-packages\webdriver_manager\core\manager.py", line 41, in _get_driver_binary_path
    binary_path = self._cache_manager.save_file_to_cache(driver, file)
                  ^^^^^^^^^^^^^^^^^^^^^^^^^^^^^^^^^^^^^^^^^^^^^^^^^^^^
  File "C:\Users\priva\Desktop\Zapros2\.venv1\Lib\site-packages\webdriver_manager\core\driver_cache.py", line 57, in save_file_to_cache
    self.__save_metadata(driver, binary_path)
  File "C:\Users\priva\Desktop\Zapros2\.venv1\Lib\site-packages\webdriver_manager\core\driver_cache.py", line 82, in __save_metadata
    metadata = self.load_metadata_content()
               ^^^^^^^^^^^^^^^^^^^^^^^^^^^^
  File "C:\Users\priva\Desktop\Zapros2\.venv1\Lib\site-packages\webdriver_manager\core\driver_cache.py", line 137, in load_metadata_content
    return json.load(outfile)
           ^^^^^^^^^^^^^^^^^^
  File "C:\Users\priva\AppData\Local\Programs\Python\Python311\Lib\json\__init__.py", line 293, in load
    return loads(fp.read(),
           ^^^^^^^^^^^^^^^^
  File "C:\Users\priva\AppData\Local\Programs\Python\Python311\Lib\json\__init__.py", line 346, in loads
    return _default_decoder.decode(s)
           ^^^^^^^^^^^^^^^^^^^^^^^^^^
  File "C:\Users\priva\AppData\Local\Programs\Python\Python311\Lib\json\decoder.py", line 337, in decode
    obj, end = self.raw_decode(s, idx=_w(s, 0).end())
               ^^^^^^^^^^^^^^^^^^^^^^^^^^^^^^^^^^^^^^
  File "C:\Users\priva\AppData\Local\Programs\Python\Python311\Lib\json\decoder.py", line 355, in raw_decode
    raise JSONDecodeError("Expecting value", s, err.value) from None
json.decoder.JSONDecodeError: Expecting value: line 1 column 1 (char 0)
2025-04-08 16:42:39 - webdriver - ERROR - Ошибка при инициализации WebDriver: Expecting value: line 1 column 1 (char 0)
Traceback (most recent call last):
  File "C:\Users\priva\Desktop\Zapros2\main.py", line 28, in init_driver
    service = Service(ChromeDriverManager().install())
                      ^^^^^^^^^^^^^^^^^^^^^^^^^^^^^^^
  File "C:\Users\priva\Desktop\Zapros2\.venv1\Lib\site-packages\webdriver_manager\chrome.py", line 40, in install
    driver_path = self._get_driver_binary_path(self.driver)
                  ^^^^^^^^^^^^^^^^^^^^^^^^^^^^^^^^^^^^^^^^^
  File "C:\Users\priva\Desktop\Zapros2\.venv1\Lib\site-packages\webdriver_manager\core\manager.py", line 41, in _get_driver_binary_path
    binary_path = self._cache_manager.save_file_to_cache(driver, file)
                  ^^^^^^^^^^^^^^^^^^^^^^^^^^^^^^^^^^^^^^^^^^^^^^^^^^^^
  File "C:\Users\priva\Desktop\Zapros2\.venv1\Lib\site-packages\webdriver_manager\core\driver_cache.py", line 57, in save_file_to_cache
    self.__save_metadata(driver, binary_path)
  File "C:\Users\priva\Desktop\Zapros2\.venv1\Lib\site-packages\webdriver_manager\core\driver_cache.py", line 82, in __save_metadata
    metadata = self.load_metadata_content()
               ^^^^^^^^^^^^^^^^^^^^^^^^^^^^
  File "C:\Users\priva\Desktop\Zapros2\.venv1\Lib\site-packages\webdriver_manager\core\driver_cache.py", line 137, in load_metadata_content
    return json.load(outfile)
           ^^^^^^^^^^^^^^^^^^
  File "C:\Users\priva\AppData\Local\Programs\Python\Python311\Lib\json\__init__.py", line 293, in load
    return loads(fp.read(),
           ^^^^^^^^^^^^^^^^
  File "C:\Users\priva\AppData\Local\Programs\Python\Python311\Lib\json\__init__.py", line 346, in loads
    return _default_decoder.decode(s)
           ^^^^^^^^^^^^^^^^^^^^^^^^^^
  File "C:\Users\priva\AppData\Local\Programs\Python\Python311\Lib\json\decoder.py", line 337, in decode
    obj, end = self.raw_decode(s, idx=_w(s, 0).end())
               ^^^^^^^^^^^^^^^^^^^^^^^^^^^^^^^^^^^^^^
  File "C:\Users\priva\AppData\Local\Programs\Python\Python311\Lib\json\decoder.py", line 355, in raw_decode
    raise JSONDecodeError("Expecting value", s, err.value) from None
json.decoder.JSONDecodeError: Expecting value: line 1 column 1 (char 0)
2025-04-08 16:42:39 - webdriver - ERROR - Ошибка при инициализации WebDriver: Expecting value: line 1 column 1 (char 0)
Traceback (most recent call last):
  File "C:\Users\priva\Desktop\Zapros2\main.py", line 28, in init_driver
    service = Service(ChromeDriverManager().install())
                      ^^^^^^^^^^^^^^^^^^^^^^^^^^^^^^^
  File "C:\Users\priva\Desktop\Zapros2\.venv1\Lib\site-packages\webdriver_manager\chrome.py", line 40, in install
    driver_path = self._get_driver_binary_path(self.driver)
                  ^^^^^^^^^^^^^^^^^^^^^^^^^^^^^^^^^^^^^^^^^
  File "C:\Users\priva\Desktop\Zapros2\.venv1\Lib\site-packages\webdriver_manager\core\manager.py", line 41, in _get_driver_binary_path
    binary_path = self._cache_manager.save_file_to_cache(driver, file)
                  ^^^^^^^^^^^^^^^^^^^^^^^^^^^^^^^^^^^^^^^^^^^^^^^^^^^^
  File "C:\Users\priva\Desktop\Zapros2\.venv1\Lib\site-packages\webdriver_manager\core\driver_cache.py", line 57, in save_file_to_cache
    self.__save_metadata(driver, binary_path)
  File "C:\Users\priva\Desktop\Zapros2\.venv1\Lib\site-packages\webdriver_manager\core\driver_cache.py", line 82, in __save_metadata
    metadata = self.load_metadata_content()
               ^^^^^^^^^^^^^^^^^^^^^^^^^^^^
  File "C:\Users\priva\Desktop\Zapros2\.venv1\Lib\site-packages\webdriver_manager\core\driver_cache.py", line 137, in load_metadata_content
    return json.load(outfile)
           ^^^^^^^^^^^^^^^^^^
  File "C:\Users\priva\AppData\Local\Programs\Python\Python311\Lib\json\__init__.py", line 293, in load
    return loads(fp.read(),
           ^^^^^^^^^^^^^^^^
  File "C:\Users\priva\AppData\Local\Programs\Python\Python311\Lib\json\__init__.py", line 346, in loads
    return _default_decoder.decode(s)
           ^^^^^^^^^^^^^^^^^^^^^^^^^^
  File "C:\Users\priva\AppData\Local\Programs\Python\Python311\Lib\json\decoder.py", line 337, in decode
    obj, end = self.raw_decode(s, idx=_w(s, 0).end())
               ^^^^^^^^^^^^^^^^^^^^^^^^^^^^^^^^^^^^^^
  File "C:\Users\priva\AppData\Local\Programs\Python\Python311\Lib\json\decoder.py", line 355, in raw_decode
    raise JSONDecodeError("Expecting value", s, err.value) from None
json.decoder.JSONDecodeError: Expecting value: line 1 column 1 (char 0)
2025-04-08 16:42:39 - webdriver - ERROR - Ошибка при инициализации WebDriver: Expecting value: line 1 column 1 (char 0)
Traceback (most recent call last):
  File "C:\Users\priva\Desktop\Zapros2\main.py", line 28, in init_driver
    service = Service(ChromeDriverManager().install())
                      ^^^^^^^^^^^^^^^^^^^^^^^^^^^^^^^
  File "C:\Users\priva\Desktop\Zapros2\.venv1\Lib\site-packages\webdriver_manager\chrome.py", line 40, in install
    driver_path = self._get_driver_binary_path(self.driver)
                  ^^^^^^^^^^^^^^^^^^^^^^^^^^^^^^^^^^^^^^^^^
  File "C:\Users\priva\Desktop\Zapros2\.venv1\Lib\site-packages\webdriver_manager\core\manager.py", line 41, in _get_driver_binary_path
    binary_path = self._cache_manager.save_file_to_cache(driver, file)
                  ^^^^^^^^^^^^^^^^^^^^^^^^^^^^^^^^^^^^^^^^^^^^^^^^^^^^
  File "C:\Users\priva\Desktop\Zapros2\.venv1\Lib\site-packages\webdriver_manager\core\driver_cache.py", line 57, in save_file_to_cache
    self.__save_metadata(driver, binary_path)
  File "C:\Users\priva\Desktop\Zapros2\.venv1\Lib\site-packages\webdriver_manager\core\driver_cache.py", line 82, in __save_metadata
    metadata = self.load_metadata_content()
               ^^^^^^^^^^^^^^^^^^^^^^^^^^^^
  File "C:\Users\priva\Desktop\Zapros2\.venv1\Lib\site-packages\webdriver_manager\core\driver_cache.py", line 137, in load_metadata_content
    return json.load(outfile)
           ^^^^^^^^^^^^^^^^^^
  File "C:\Users\priva\AppData\Local\Programs\Python\Python311\Lib\json\__init__.py", line 293, in load
    return loads(fp.read(),
           ^^^^^^^^^^^^^^^^
  File "C:\Users\priva\AppData\Local\Programs\Python\Python311\Lib\json\__init__.py", line 346, in loads
    return _default_decoder.decode(s)
           ^^^^^^^^^^^^^^^^^^^^^^^^^^
  File "C:\Users\priva\AppData\Local\Programs\Python\Python311\Lib\json\decoder.py", line 337, in decode
    obj, end = self.raw_decode(s, idx=_w(s, 0).end())
               ^^^^^^^^^^^^^^^^^^^^^^^^^^^^^^^^^^^^^^
  File "C:\Users\priva\AppData\Local\Programs\Python\Python311\Lib\json\decoder.py", line 355, in raw_decode
    raise JSONDecodeError("Expecting value", s, err.value) from None
json.decoder.JSONDecodeError: Expecting value: line 1 column 1 (char 0)
