2025-04-01 19:49:50 - webdriver - ERROR - Ошибка при инициализации WebDriver: Message: 'chromedriver.exe' executable may have wrong permissions.
Traceback (most recent call last):
  File "C:\Users\priva\Desktop\Zapros2\.venv\Lib\site-packages\selenium\webdriver\common\service.py", line 219, in _start_process
    self.process = subprocess.Popen(
                   ~~~~~~~~~~~~~~~~^
        cmd,
        ^^^^
    ...<7 lines>...
        **self.popen_kw,
        ^^^^^^^^^^^^^^^^
    )
    ^
  File "C:\Users\priva\AppData\Local\Programs\Python\Python313\Lib\subprocess.py", line 1038, in __init__
    self._execute_child(args, executable, preexec_fn, close_fds,
    ~~~~~~~~~~~~~~~~~~~^^^^^^^^^^^^^^^^^^^^^^^^^^^^^^^^^^^^^^^^^
                        pass_fds, cwd, env,
                        ^^^^^^^^^^^^^^^^^^^
    ...<5 lines>...
                        gid, gids, uid, umask,
                        ^^^^^^^^^^^^^^^^^^^^^^
                        start_new_session, process_group)
                        ^^^^^^^^^^^^^^^^^^^^^^^^^^^^^^^^^
  File "C:\Users\priva\AppData\Local\Programs\Python\Python313\Lib\subprocess.py", line 1550, in _execute_child
    hp, ht, pid, tid = _winapi.CreateProcess(executable, args,
                       ~~~~~~~~~~~~~~~~~~~~~^^^^^^^^^^^^^^^^^^
                             # no special security
                             ^^^^^^^^^^^^^^^^^^^^^
    ...<4 lines>...
                             cwd,
                             ^^^^
                             startupinfo)
                             ^^^^^^^^^^^^
PermissionError: [WinError 32] Процесс не может получить доступ к файлу, так как этот файл занят другим процессом

The above exception was the direct cause of the following exception:

Traceback (most recent call last):
  File "C:\Users\priva\Desktop\Zapros2\main.py", line 29, in init_driver
    driver = webdriver.Chrome(service=service, options=options)
  File "C:\Users\priva\Desktop\Zapros2\.venv\Lib\site-packages\selenium\webdriver\chrome\webdriver.py", line 45, in __init__
    super().__init__(
    ~~~~~~~~~~~~~~~~^
        browser_name=DesiredCapabilities.CHROME["browserName"],
        ^^^^^^^^^^^^^^^^^^^^^^^^^^^^^^^^^^^^^^^^^^^^^^^^^^^^^^^
    ...<3 lines>...
        keep_alive=keep_alive,
        ^^^^^^^^^^^^^^^^^^^^^^
    )
    ^
  File "C:\Users\priva\Desktop\Zapros2\.venv\Lib\site-packages\selenium\webdriver\chromium\webdriver.py", line 55, in __init__
    self.service.start()
    ~~~~~~~~~~~~~~~~~~^^
  File "C:\Users\priva\Desktop\Zapros2\.venv\Lib\site-packages\selenium\webdriver\common\service.py", line 109, in start
    self._start_process(self._path)
    ~~~~~~~~~~~~~~~~~~~^^^^^^^^^^^^
  File "C:\Users\priva\Desktop\Zapros2\.venv\Lib\site-packages\selenium\webdriver\common\service.py", line 243, in _start_process
    raise WebDriverException(
        f"'{os.path.basename(self._path)}' executable may have wrong permissions."
    ) from err
selenium.common.exceptions.WebDriverException: Message: 'chromedriver.exe' executable may have wrong permissions.

2025-04-01 19:49:50 - webdriver - ERROR - Ошибка при инициализации WebDriver: Message: 'chromedriver.exe' executable may have wrong permissions.
Traceback (most recent call last):
  File "C:\Users\priva\Desktop\Zapros2\.venv\Lib\site-packages\selenium\webdriver\common\service.py", line 219, in _start_process
    self.process = subprocess.Popen(
                   ~~~~~~~~~~~~~~~~^
        cmd,
        ^^^^
    ...<7 lines>...
        **self.popen_kw,
        ^^^^^^^^^^^^^^^^
    )
    ^
  File "C:\Users\priva\AppData\Local\Programs\Python\Python313\Lib\subprocess.py", line 1038, in __init__
    self._execute_child(args, executable, preexec_fn, close_fds,
    ~~~~~~~~~~~~~~~~~~~^^^^^^^^^^^^^^^^^^^^^^^^^^^^^^^^^^^^^^^^^
                        pass_fds, cwd, env,
                        ^^^^^^^^^^^^^^^^^^^
    ...<5 lines>...
                        gid, gids, uid, umask,
                        ^^^^^^^^^^^^^^^^^^^^^^
                        start_new_session, process_group)
                        ^^^^^^^^^^^^^^^^^^^^^^^^^^^^^^^^^
  File "C:\Users\priva\AppData\Local\Programs\Python\Python313\Lib\subprocess.py", line 1550, in _execute_child
    hp, ht, pid, tid = _winapi.CreateProcess(executable, args,
                       ~~~~~~~~~~~~~~~~~~~~~^^^^^^^^^^^^^^^^^^
                             # no special security
                             ^^^^^^^^^^^^^^^^^^^^^
    ...<4 lines>...
                             cwd,
                             ^^^^
                             startupinfo)
                             ^^^^^^^^^^^^
PermissionError: [WinError 32] Процесс не может получить доступ к файлу, так как этот файл занят другим процессом

The above exception was the direct cause of the following exception:

Traceback (most recent call last):
  File "C:\Users\priva\Desktop\Zapros2\main.py", line 29, in init_driver
    driver = webdriver.Chrome(service=service, options=options)
  File "C:\Users\priva\Desktop\Zapros2\.venv\Lib\site-packages\selenium\webdriver\chrome\webdriver.py", line 45, in __init__
    super().__init__(
    ~~~~~~~~~~~~~~~~^
        browser_name=DesiredCapabilities.CHROME["browserName"],
        ^^^^^^^^^^^^^^^^^^^^^^^^^^^^^^^^^^^^^^^^^^^^^^^^^^^^^^^
    ...<3 lines>...
        keep_alive=keep_alive,
        ^^^^^^^^^^^^^^^^^^^^^^
    )
    ^
  File "C:\Users\priva\Desktop\Zapros2\.venv\Lib\site-packages\selenium\webdriver\chromium\webdriver.py", line 55, in __init__
    self.service.start()
    ~~~~~~~~~~~~~~~~~~^^
  File "C:\Users\priva\Desktop\Zapros2\.venv\Lib\site-packages\selenium\webdriver\common\service.py", line 109, in start
    self._start_process(self._path)
    ~~~~~~~~~~~~~~~~~~~^^^^^^^^^^^^
  File "C:\Users\priva\Desktop\Zapros2\.venv\Lib\site-packages\selenium\webdriver\common\service.py", line 243, in _start_process
    raise WebDriverException(
        f"'{os.path.basename(self._path)}' executable may have wrong permissions."
    ) from err
selenium.common.exceptions.WebDriverException: Message: 'chromedriver.exe' executable may have wrong permissions.

2025-04-01 19:49:50 - webdriver - ERROR - Ошибка при инициализации WebDriver: Message: 'chromedriver.exe' executable may have wrong permissions.
Traceback (most recent call last):
  File "C:\Users\priva\Desktop\Zapros2\.venv\Lib\site-packages\selenium\webdriver\common\service.py", line 219, in _start_process
    self.process = subprocess.Popen(
                   ~~~~~~~~~~~~~~~~^
        cmd,
        ^^^^
    ...<7 lines>...
        **self.popen_kw,
        ^^^^^^^^^^^^^^^^
    )
    ^
  File "C:\Users\priva\AppData\Local\Programs\Python\Python313\Lib\subprocess.py", line 1038, in __init__
    self._execute_child(args, executable, preexec_fn, close_fds,
    ~~~~~~~~~~~~~~~~~~~^^^^^^^^^^^^^^^^^^^^^^^^^^^^^^^^^^^^^^^^^
                        pass_fds, cwd, env,
                        ^^^^^^^^^^^^^^^^^^^
    ...<5 lines>...
                        gid, gids, uid, umask,
                        ^^^^^^^^^^^^^^^^^^^^^^
                        start_new_session, process_group)
                        ^^^^^^^^^^^^^^^^^^^^^^^^^^^^^^^^^
  File "C:\Users\priva\AppData\Local\Programs\Python\Python313\Lib\subprocess.py", line 1550, in _execute_child
    hp, ht, pid, tid = _winapi.CreateProcess(executable, args,
                       ~~~~~~~~~~~~~~~~~~~~~^^^^^^^^^^^^^^^^^^
                             # no special security
                             ^^^^^^^^^^^^^^^^^^^^^
    ...<4 lines>...
                             cwd,
                             ^^^^
                             startupinfo)
                             ^^^^^^^^^^^^
PermissionError: [WinError 32] Процесс не может получить доступ к файлу, так как этот файл занят другим процессом

The above exception was the direct cause of the following exception:

Traceback (most recent call last):
  File "C:\Users\priva\Desktop\Zapros2\main.py", line 29, in init_driver
    driver = webdriver.Chrome(service=service, options=options)
  File "C:\Users\priva\Desktop\Zapros2\.venv\Lib\site-packages\selenium\webdriver\chrome\webdriver.py", line 45, in __init__
    super().__init__(
    ~~~~~~~~~~~~~~~~^
        browser_name=DesiredCapabilities.CHROME["browserName"],
        ^^^^^^^^^^^^^^^^^^^^^^^^^^^^^^^^^^^^^^^^^^^^^^^^^^^^^^^
    ...<3 lines>...
        keep_alive=keep_alive,
        ^^^^^^^^^^^^^^^^^^^^^^
    )
    ^
  File "C:\Users\priva\Desktop\Zapros2\.venv\Lib\site-packages\selenium\webdriver\chromium\webdriver.py", line 55, in __init__
    self.service.start()
    ~~~~~~~~~~~~~~~~~~^^
  File "C:\Users\priva\Desktop\Zapros2\.venv\Lib\site-packages\selenium\webdriver\common\service.py", line 109, in start
    self._start_process(self._path)
    ~~~~~~~~~~~~~~~~~~~^^^^^^^^^^^^
  File "C:\Users\priva\Desktop\Zapros2\.venv\Lib\site-packages\selenium\webdriver\common\service.py", line 243, in _start_process
    raise WebDriverException(
        f"'{os.path.basename(self._path)}' executable may have wrong permissions."
    ) from err
selenium.common.exceptions.WebDriverException: Message: 'chromedriver.exe' executable may have wrong permissions.

2025-04-01 19:49:50 - webdriver - ERROR - Ошибка при инициализации WebDriver: Message: 'chromedriver.exe' executable may have wrong permissions.
Traceback (most recent call last):
  File "C:\Users\priva\Desktop\Zapros2\.venv\Lib\site-packages\selenium\webdriver\common\service.py", line 219, in _start_process
    self.process = subprocess.Popen(
                   ~~~~~~~~~~~~~~~~^
        cmd,
        ^^^^
    ...<7 lines>...
        **self.popen_kw,
        ^^^^^^^^^^^^^^^^
    )
    ^
  File "C:\Users\priva\AppData\Local\Programs\Python\Python313\Lib\subprocess.py", line 1038, in __init__
    self._execute_child(args, executable, preexec_fn, close_fds,
    ~~~~~~~~~~~~~~~~~~~^^^^^^^^^^^^^^^^^^^^^^^^^^^^^^^^^^^^^^^^^
                        pass_fds, cwd, env,
                        ^^^^^^^^^^^^^^^^^^^
    ...<5 lines>...
                        gid, gids, uid, umask,
                        ^^^^^^^^^^^^^^^^^^^^^^
                        start_new_session, process_group)
                        ^^^^^^^^^^^^^^^^^^^^^^^^^^^^^^^^^
  File "C:\Users\priva\AppData\Local\Programs\Python\Python313\Lib\subprocess.py", line 1550, in _execute_child
    hp, ht, pid, tid = _winapi.CreateProcess(executable, args,
                       ~~~~~~~~~~~~~~~~~~~~~^^^^^^^^^^^^^^^^^^
                             # no special security
                             ^^^^^^^^^^^^^^^^^^^^^
    ...<4 lines>...
                             cwd,
                             ^^^^
                             startupinfo)
                             ^^^^^^^^^^^^
PermissionError: [WinError 32] Процесс не может получить доступ к файлу, так как этот файл занят другим процессом

The above exception was the direct cause of the following exception:

Traceback (most recent call last):
  File "C:\Users\priva\Desktop\Zapros2\main.py", line 29, in init_driver
    driver = webdriver.Chrome(service=service, options=options)
  File "C:\Users\priva\Desktop\Zapros2\.venv\Lib\site-packages\selenium\webdriver\chrome\webdriver.py", line 45, in __init__
    super().__init__(
    ~~~~~~~~~~~~~~~~^
        browser_name=DesiredCapabilities.CHROME["browserName"],
        ^^^^^^^^^^^^^^^^^^^^^^^^^^^^^^^^^^^^^^^^^^^^^^^^^^^^^^^
    ...<3 lines>...
        keep_alive=keep_alive,
        ^^^^^^^^^^^^^^^^^^^^^^
    )
    ^
  File "C:\Users\priva\Desktop\Zapros2\.venv\Lib\site-packages\selenium\webdriver\chromium\webdriver.py", line 55, in __init__
    self.service.start()
    ~~~~~~~~~~~~~~~~~~^^
  File "C:\Users\priva\Desktop\Zapros2\.venv\Lib\site-packages\selenium\webdriver\common\service.py", line 109, in start
    self._start_process(self._path)
    ~~~~~~~~~~~~~~~~~~~^^^^^^^^^^^^
  File "C:\Users\priva\Desktop\Zapros2\.venv\Lib\site-packages\selenium\webdriver\common\service.py", line 243, in _start_process
    raise WebDriverException(
        f"'{os.path.basename(self._path)}' executable may have wrong permissions."
    ) from err
selenium.common.exceptions.WebDriverException: Message: 'chromedriver.exe' executable may have wrong permissions.

2025-04-01 19:49:50 - webdriver - ERROR - Ошибка при инициализации WebDriver: Message: 'chromedriver.exe' executable may have wrong permissions.
Traceback (most recent call last):
  File "C:\Users\priva\Desktop\Zapros2\.venv\Lib\site-packages\selenium\webdriver\common\service.py", line 219, in _start_process
    self.process = subprocess.Popen(
                   ~~~~~~~~~~~~~~~~^
        cmd,
        ^^^^
    ...<7 lines>...
        **self.popen_kw,
        ^^^^^^^^^^^^^^^^
    )
    ^
  File "C:\Users\priva\AppData\Local\Programs\Python\Python313\Lib\subprocess.py", line 1038, in __init__
    self._execute_child(args, executable, preexec_fn, close_fds,
    ~~~~~~~~~~~~~~~~~~~^^^^^^^^^^^^^^^^^^^^^^^^^^^^^^^^^^^^^^^^^
                        pass_fds, cwd, env,
                        ^^^^^^^^^^^^^^^^^^^
    ...<5 lines>...
                        gid, gids, uid, umask,
                        ^^^^^^^^^^^^^^^^^^^^^^
                        start_new_session, process_group)
                        ^^^^^^^^^^^^^^^^^^^^^^^^^^^^^^^^^
  File "C:\Users\priva\AppData\Local\Programs\Python\Python313\Lib\subprocess.py", line 1550, in _execute_child
    hp, ht, pid, tid = _winapi.CreateProcess(executable, args,
                       ~~~~~~~~~~~~~~~~~~~~~^^^^^^^^^^^^^^^^^^
                             # no special security
                             ^^^^^^^^^^^^^^^^^^^^^
    ...<4 lines>...
                             cwd,
                             ^^^^
                             startupinfo)
                             ^^^^^^^^^^^^
PermissionError: [WinError 32] Процесс не может получить доступ к файлу, так как этот файл занят другим процессом

The above exception was the direct cause of the following exception:

Traceback (most recent call last):
  File "C:\Users\priva\Desktop\Zapros2\main.py", line 29, in init_driver
    driver = webdriver.Chrome(service=service, options=options)
  File "C:\Users\priva\Desktop\Zapros2\.venv\Lib\site-packages\selenium\webdriver\chrome\webdriver.py", line 45, in __init__
    super().__init__(
    ~~~~~~~~~~~~~~~~^
        browser_name=DesiredCapabilities.CHROME["browserName"],
        ^^^^^^^^^^^^^^^^^^^^^^^^^^^^^^^^^^^^^^^^^^^^^^^^^^^^^^^
    ...<3 lines>...
        keep_alive=keep_alive,
        ^^^^^^^^^^^^^^^^^^^^^^
    )
    ^
  File "C:\Users\priva\Desktop\Zapros2\.venv\Lib\site-packages\selenium\webdriver\chromium\webdriver.py", line 55, in __init__
    self.service.start()
    ~~~~~~~~~~~~~~~~~~^^
  File "C:\Users\priva\Desktop\Zapros2\.venv\Lib\site-packages\selenium\webdriver\common\service.py", line 109, in start
    self._start_process(self._path)
    ~~~~~~~~~~~~~~~~~~~^^^^^^^^^^^^
  File "C:\Users\priva\Desktop\Zapros2\.venv\Lib\site-packages\selenium\webdriver\common\service.py", line 243, in _start_process
    raise WebDriverException(
        f"'{os.path.basename(self._path)}' executable may have wrong permissions."
    ) from err
selenium.common.exceptions.WebDriverException: Message: 'chromedriver.exe' executable may have wrong permissions.

2025-04-01 19:49:50 - webdriver - ERROR - Ошибка при инициализации WebDriver: Truncated central directory
Traceback (most recent call last):
  File "C:\Users\priva\Desktop\Zapros2\main.py", line 28, in init_driver
    service = Service(ChromeDriverManager().install())
                      ~~~~~~~~~~~~~~~~~~~~~~~~~~~~~^^
  File "C:\Users\priva\Desktop\Zapros2\.venv\Lib\site-packages\webdriver_manager\chrome.py", line 40, in install
    driver_path = self._get_driver_binary_path(self.driver)
  File "C:\Users\priva\Desktop\Zapros2\.venv\Lib\site-packages\webdriver_manager\core\manager.py", line 41, in _get_driver_binary_path
    binary_path = self._cache_manager.save_file_to_cache(driver, file)
  File "C:\Users\priva\Desktop\Zapros2\.venv\Lib\site-packages\webdriver_manager\core\driver_cache.py", line 54, in save_file_to_cache
    files = self.unpack_archive(archive, path)
  File "C:\Users\priva\Desktop\Zapros2\.venv\Lib\site-packages\webdriver_manager\core\driver_cache.py", line 49, in unpack_archive
    return self._file_manager.unpack_archive(archive, path)
           ~~~~~~~~~~~~~~~~~~~~~~~~~~~~~~~~~^^^^^^^^^^^^^^^
  File "C:\Users\priva\Desktop\Zapros2\.venv\Lib\site-packages\webdriver_manager\core\file_manager.py", line 57, in unpack_archive
    return self.__extract_zip(archive_file, target_dir)
           ~~~~~~~~~~~~~~~~~~^^^^^^^^^^^^^^^^^^^^^^^^^^
  File "C:\Users\priva\Desktop\Zapros2\.venv\Lib\site-packages\webdriver_manager\core\file_manager.py", line 63, in __extract_zip
    archive = zip_class(archive_file.file_path)
  File "C:\Users\priva\AppData\Local\Programs\Python\Python313\Lib\zipfile\__init__.py", line 1385, in __init__
    self._RealGetContents()
    ~~~~~~~~~~~~~~~~~~~~~^^
  File "C:\Users\priva\AppData\Local\Programs\Python\Python313\Lib\zipfile\__init__.py", line 1479, in _RealGetContents
    raise BadZipFile("Truncated central directory")
zipfile.BadZipFile: Truncated central directory
2025-04-01 19:49:50 - webdriver - ERROR - Ошибка при инициализации WebDriver: File is not a zip file
Traceback (most recent call last):
  File "C:\Users\priva\Desktop\Zapros2\main.py", line 28, in init_driver
    service = Service(ChromeDriverManager().install())
                      ~~~~~~~~~~~~~~~~~~~~~~~~~~~~~^^
  File "C:\Users\priva\Desktop\Zapros2\.venv\Lib\site-packages\webdriver_manager\chrome.py", line 40, in install
    driver_path = self._get_driver_binary_path(self.driver)
  File "C:\Users\priva\Desktop\Zapros2\.venv\Lib\site-packages\webdriver_manager\core\manager.py", line 41, in _get_driver_binary_path
    binary_path = self._cache_manager.save_file_to_cache(driver, file)
  File "C:\Users\priva\Desktop\Zapros2\.venv\Lib\site-packages\webdriver_manager\core\driver_cache.py", line 54, in save_file_to_cache
    files = self.unpack_archive(archive, path)
  File "C:\Users\priva\Desktop\Zapros2\.venv\Lib\site-packages\webdriver_manager\core\driver_cache.py", line 49, in unpack_archive
    return self._file_manager.unpack_archive(archive, path)
           ~~~~~~~~~~~~~~~~~~~~~~~~~~~~~~~~~^^^^^^^^^^^^^^^
  File "C:\Users\priva\Desktop\Zapros2\.venv\Lib\site-packages\webdriver_manager\core\file_manager.py", line 57, in unpack_archive
    return self.__extract_zip(archive_file, target_dir)
           ~~~~~~~~~~~~~~~~~~^^^^^^^^^^^^^^^^^^^^^^^^^^
  File "C:\Users\priva\Desktop\Zapros2\.venv\Lib\site-packages\webdriver_manager\core\file_manager.py", line 63, in __extract_zip
    archive = zip_class(archive_file.file_path)
  File "C:\Users\priva\AppData\Local\Programs\Python\Python313\Lib\zipfile\__init__.py", line 1385, in __init__
    self._RealGetContents()
    ~~~~~~~~~~~~~~~~~~~~~^^
  File "C:\Users\priva\AppData\Local\Programs\Python\Python313\Lib\zipfile\__init__.py", line 1452, in _RealGetContents
    raise BadZipFile("File is not a zip file")
zipfile.BadZipFile: File is not a zip file
2025-04-01 19:49:50 - webdriver - ERROR - Ошибка при инициализации WebDriver: Message: 'chromedriver.exe' executable may have wrong permissions.
Traceback (most recent call last):
  File "C:\Users\priva\Desktop\Zapros2\.venv\Lib\site-packages\selenium\webdriver\common\service.py", line 219, in _start_process
    self.process = subprocess.Popen(
                   ~~~~~~~~~~~~~~~~^
        cmd,
        ^^^^
    ...<7 lines>...
        **self.popen_kw,
        ^^^^^^^^^^^^^^^^
    )
    ^
  File "C:\Users\priva\AppData\Local\Programs\Python\Python313\Lib\subprocess.py", line 1038, in __init__
    self._execute_child(args, executable, preexec_fn, close_fds,
    ~~~~~~~~~~~~~~~~~~~^^^^^^^^^^^^^^^^^^^^^^^^^^^^^^^^^^^^^^^^^
                        pass_fds, cwd, env,
                        ^^^^^^^^^^^^^^^^^^^
    ...<5 lines>...
                        gid, gids, uid, umask,
                        ^^^^^^^^^^^^^^^^^^^^^^
                        start_new_session, process_group)
                        ^^^^^^^^^^^^^^^^^^^^^^^^^^^^^^^^^
  File "C:\Users\priva\AppData\Local\Programs\Python\Python313\Lib\subprocess.py", line 1550, in _execute_child
    hp, ht, pid, tid = _winapi.CreateProcess(executable, args,
                       ~~~~~~~~~~~~~~~~~~~~~^^^^^^^^^^^^^^^^^^
                             # no special security
                             ^^^^^^^^^^^^^^^^^^^^^
    ...<4 lines>...
                             cwd,
                             ^^^^
                             startupinfo)
                             ^^^^^^^^^^^^
PermissionError: [WinError 32] Процесс не может получить доступ к файлу, так как этот файл занят другим процессом

The above exception was the direct cause of the following exception:

Traceback (most recent call last):
  File "C:\Users\priva\Desktop\Zapros2\main.py", line 29, in init_driver
    driver = webdriver.Chrome(service=service, options=options)
  File "C:\Users\priva\Desktop\Zapros2\.venv\Lib\site-packages\selenium\webdriver\chrome\webdriver.py", line 45, in __init__
    super().__init__(
    ~~~~~~~~~~~~~~~~^
        browser_name=DesiredCapabilities.CHROME["browserName"],
        ^^^^^^^^^^^^^^^^^^^^^^^^^^^^^^^^^^^^^^^^^^^^^^^^^^^^^^^
    ...<3 lines>...
        keep_alive=keep_alive,
        ^^^^^^^^^^^^^^^^^^^^^^
    )
    ^
  File "C:\Users\priva\Desktop\Zapros2\.venv\Lib\site-packages\selenium\webdriver\chromium\webdriver.py", line 55, in __init__
    self.service.start()
    ~~~~~~~~~~~~~~~~~~^^
  File "C:\Users\priva\Desktop\Zapros2\.venv\Lib\site-packages\selenium\webdriver\common\service.py", line 109, in start
    self._start_process(self._path)
    ~~~~~~~~~~~~~~~~~~~^^^^^^^^^^^^
  File "C:\Users\priva\Desktop\Zapros2\.venv\Lib\site-packages\selenium\webdriver\common\service.py", line 243, in _start_process
    raise WebDriverException(
        f"'{os.path.basename(self._path)}' executable may have wrong permissions."
    ) from err
selenium.common.exceptions.WebDriverException: Message: 'chromedriver.exe' executable may have wrong permissions.

2025-04-01 19:49:51 - webdriver - ERROR - Ошибка при инициализации WebDriver: Message: 'chromedriver.exe' executable may have wrong permissions.
Traceback (most recent call last):
  File "C:\Users\priva\Desktop\Zapros2\.venv\Lib\site-packages\selenium\webdriver\common\service.py", line 219, in _start_process
    self.process = subprocess.Popen(
                   ~~~~~~~~~~~~~~~~^
        cmd,
        ^^^^
    ...<7 lines>...
        **self.popen_kw,
        ^^^^^^^^^^^^^^^^
    )
    ^
  File "C:\Users\priva\AppData\Local\Programs\Python\Python313\Lib\subprocess.py", line 1038, in __init__
    self._execute_child(args, executable, preexec_fn, close_fds,
    ~~~~~~~~~~~~~~~~~~~^^^^^^^^^^^^^^^^^^^^^^^^^^^^^^^^^^^^^^^^^
                        pass_fds, cwd, env,
                        ^^^^^^^^^^^^^^^^^^^
    ...<5 lines>...
                        gid, gids, uid, umask,
                        ^^^^^^^^^^^^^^^^^^^^^^
                        start_new_session, process_group)
                        ^^^^^^^^^^^^^^^^^^^^^^^^^^^^^^^^^
  File "C:\Users\priva\AppData\Local\Programs\Python\Python313\Lib\subprocess.py", line 1550, in _execute_child
    hp, ht, pid, tid = _winapi.CreateProcess(executable, args,
                       ~~~~~~~~~~~~~~~~~~~~~^^^^^^^^^^^^^^^^^^
                             # no special security
                             ^^^^^^^^^^^^^^^^^^^^^
    ...<4 lines>...
                             cwd,
                             ^^^^
                             startupinfo)
                             ^^^^^^^^^^^^
PermissionError: [WinError 32] Процесс не может получить доступ к файлу, так как этот файл занят другим процессом

The above exception was the direct cause of the following exception:

Traceback (most recent call last):
  File "C:\Users\priva\Desktop\Zapros2\main.py", line 29, in init_driver
    driver = webdriver.Chrome(service=service, options=options)
  File "C:\Users\priva\Desktop\Zapros2\.venv\Lib\site-packages\selenium\webdriver\chrome\webdriver.py", line 45, in __init__
    super().__init__(
    ~~~~~~~~~~~~~~~~^
        browser_name=DesiredCapabilities.CHROME["browserName"],
        ^^^^^^^^^^^^^^^^^^^^^^^^^^^^^^^^^^^^^^^^^^^^^^^^^^^^^^^
    ...<3 lines>...
        keep_alive=keep_alive,
        ^^^^^^^^^^^^^^^^^^^^^^
    )
    ^
  File "C:\Users\priva\Desktop\Zapros2\.venv\Lib\site-packages\selenium\webdriver\chromium\webdriver.py", line 55, in __init__
    self.service.start()
    ~~~~~~~~~~~~~~~~~~^^
  File "C:\Users\priva\Desktop\Zapros2\.venv\Lib\site-packages\selenium\webdriver\common\service.py", line 109, in start
    self._start_process(self._path)
    ~~~~~~~~~~~~~~~~~~~^^^^^^^^^^^^
  File "C:\Users\priva\Desktop\Zapros2\.venv\Lib\site-packages\selenium\webdriver\common\service.py", line 243, in _start_process
    raise WebDriverException(
        f"'{os.path.basename(self._path)}' executable may have wrong permissions."
    ) from err
selenium.common.exceptions.WebDriverException: Message: 'chromedriver.exe' executable may have wrong permissions.

2025-04-01 19:49:51 - webdriver - ERROR - Ошибка при инициализации WebDriver: Message: 'chromedriver.exe' executable may have wrong permissions.
Traceback (most recent call last):
  File "C:\Users\priva\Desktop\Zapros2\.venv\Lib\site-packages\selenium\webdriver\common\service.py", line 219, in _start_process
    self.process = subprocess.Popen(
                   ~~~~~~~~~~~~~~~~^
        cmd,
        ^^^^
    ...<7 lines>...
        **self.popen_kw,
        ^^^^^^^^^^^^^^^^
    )
    ^
  File "C:\Users\priva\AppData\Local\Programs\Python\Python313\Lib\subprocess.py", line 1038, in __init__
    self._execute_child(args, executable, preexec_fn, close_fds,
    ~~~~~~~~~~~~~~~~~~~^^^^^^^^^^^^^^^^^^^^^^^^^^^^^^^^^^^^^^^^^
                        pass_fds, cwd, env,
                        ^^^^^^^^^^^^^^^^^^^
    ...<5 lines>...
                        gid, gids, uid, umask,
                        ^^^^^^^^^^^^^^^^^^^^^^
                        start_new_session, process_group)
                        ^^^^^^^^^^^^^^^^^^^^^^^^^^^^^^^^^
  File "C:\Users\priva\AppData\Local\Programs\Python\Python313\Lib\subprocess.py", line 1550, in _execute_child
    hp, ht, pid, tid = _winapi.CreateProcess(executable, args,
                       ~~~~~~~~~~~~~~~~~~~~~^^^^^^^^^^^^^^^^^^
                             # no special security
                             ^^^^^^^^^^^^^^^^^^^^^
    ...<4 lines>...
                             cwd,
                             ^^^^
                             startupinfo)
                             ^^^^^^^^^^^^
PermissionError: [WinError 32] Процесс не может получить доступ к файлу, так как этот файл занят другим процессом

The above exception was the direct cause of the following exception:

Traceback (most recent call last):
  File "C:\Users\priva\Desktop\Zapros2\main.py", line 29, in init_driver
    driver = webdriver.Chrome(service=service, options=options)
  File "C:\Users\priva\Desktop\Zapros2\.venv\Lib\site-packages\selenium\webdriver\chrome\webdriver.py", line 45, in __init__
    super().__init__(
    ~~~~~~~~~~~~~~~~^
        browser_name=DesiredCapabilities.CHROME["browserName"],
        ^^^^^^^^^^^^^^^^^^^^^^^^^^^^^^^^^^^^^^^^^^^^^^^^^^^^^^^
    ...<3 lines>...
        keep_alive=keep_alive,
        ^^^^^^^^^^^^^^^^^^^^^^
    )
    ^
  File "C:\Users\priva\Desktop\Zapros2\.venv\Lib\site-packages\selenium\webdriver\chromium\webdriver.py", line 55, in __init__
    self.service.start()
    ~~~~~~~~~~~~~~~~~~^^
  File "C:\Users\priva\Desktop\Zapros2\.venv\Lib\site-packages\selenium\webdriver\common\service.py", line 109, in start
    self._start_process(self._path)
    ~~~~~~~~~~~~~~~~~~~^^^^^^^^^^^^
  File "C:\Users\priva\Desktop\Zapros2\.venv\Lib\site-packages\selenium\webdriver\common\service.py", line 243, in _start_process
    raise WebDriverException(
        f"'{os.path.basename(self._path)}' executable may have wrong permissions."
    ) from err
selenium.common.exceptions.WebDriverException: Message: 'chromedriver.exe' executable may have wrong permissions.

2025-04-01 19:49:51 - webdriver - ERROR - Ошибка при инициализации WebDriver: Message: 'chromedriver.exe' executable may have wrong permissions.
Traceback (most recent call last):
  File "C:\Users\priva\Desktop\Zapros2\.venv\Lib\site-packages\selenium\webdriver\common\service.py", line 219, in _start_process
    self.process = subprocess.Popen(
                   ~~~~~~~~~~~~~~~~^
        cmd,
        ^^^^
    ...<7 lines>...
        **self.popen_kw,
        ^^^^^^^^^^^^^^^^
    )
    ^
  File "C:\Users\priva\AppData\Local\Programs\Python\Python313\Lib\subprocess.py", line 1038, in __init__
    self._execute_child(args, executable, preexec_fn, close_fds,
    ~~~~~~~~~~~~~~~~~~~^^^^^^^^^^^^^^^^^^^^^^^^^^^^^^^^^^^^^^^^^
                        pass_fds, cwd, env,
                        ^^^^^^^^^^^^^^^^^^^
    ...<5 lines>...
                        gid, gids, uid, umask,
                        ^^^^^^^^^^^^^^^^^^^^^^
                        start_new_session, process_group)
                        ^^^^^^^^^^^^^^^^^^^^^^^^^^^^^^^^^
  File "C:\Users\priva\AppData\Local\Programs\Python\Python313\Lib\subprocess.py", line 1550, in _execute_child
    hp, ht, pid, tid = _winapi.CreateProcess(executable, args,
                       ~~~~~~~~~~~~~~~~~~~~~^^^^^^^^^^^^^^^^^^
                             # no special security
                             ^^^^^^^^^^^^^^^^^^^^^
    ...<4 lines>...
                             cwd,
                             ^^^^
                             startupinfo)
                             ^^^^^^^^^^^^
PermissionError: [WinError 32] Процесс не может получить доступ к файлу, так как этот файл занят другим процессом

The above exception was the direct cause of the following exception:

Traceback (most recent call last):
  File "C:\Users\priva\Desktop\Zapros2\main.py", line 29, in init_driver
    driver = webdriver.Chrome(service=service, options=options)
  File "C:\Users\priva\Desktop\Zapros2\.venv\Lib\site-packages\selenium\webdriver\chrome\webdriver.py", line 45, in __init__
    super().__init__(
    ~~~~~~~~~~~~~~~~^
        browser_name=DesiredCapabilities.CHROME["browserName"],
        ^^^^^^^^^^^^^^^^^^^^^^^^^^^^^^^^^^^^^^^^^^^^^^^^^^^^^^^
    ...<3 lines>...
        keep_alive=keep_alive,
        ^^^^^^^^^^^^^^^^^^^^^^
    )
    ^
  File "C:\Users\priva\Desktop\Zapros2\.venv\Lib\site-packages\selenium\webdriver\chromium\webdriver.py", line 55, in __init__
    self.service.start()
    ~~~~~~~~~~~~~~~~~~^^
  File "C:\Users\priva\Desktop\Zapros2\.venv\Lib\site-packages\selenium\webdriver\common\service.py", line 109, in start
    self._start_process(self._path)
    ~~~~~~~~~~~~~~~~~~~^^^^^^^^^^^^
  File "C:\Users\priva\Desktop\Zapros2\.venv\Lib\site-packages\selenium\webdriver\common\service.py", line 243, in _start_process
    raise WebDriverException(
        f"'{os.path.basename(self._path)}' executable may have wrong permissions."
    ) from err
selenium.common.exceptions.WebDriverException: Message: 'chromedriver.exe' executable may have wrong permissions.

2025-04-01 19:49:51 - webdriver - ERROR - Ошибка при инициализации WebDriver: Message: 'chromedriver.exe' executable may have wrong permissions.
Traceback (most recent call last):
  File "C:\Users\priva\Desktop\Zapros2\.venv\Lib\site-packages\selenium\webdriver\common\service.py", line 219, in _start_process
    self.process = subprocess.Popen(
                   ~~~~~~~~~~~~~~~~^
        cmd,
        ^^^^
    ...<7 lines>...
        **self.popen_kw,
        ^^^^^^^^^^^^^^^^
    )
    ^
  File "C:\Users\priva\AppData\Local\Programs\Python\Python313\Lib\subprocess.py", line 1038, in __init__
    self._execute_child(args, executable, preexec_fn, close_fds,
    ~~~~~~~~~~~~~~~~~~~^^^^^^^^^^^^^^^^^^^^^^^^^^^^^^^^^^^^^^^^^
                        pass_fds, cwd, env,
                        ^^^^^^^^^^^^^^^^^^^
    ...<5 lines>...
                        gid, gids, uid, umask,
                        ^^^^^^^^^^^^^^^^^^^^^^
                        start_new_session, process_group)
                        ^^^^^^^^^^^^^^^^^^^^^^^^^^^^^^^^^
  File "C:\Users\priva\AppData\Local\Programs\Python\Python313\Lib\subprocess.py", line 1550, in _execute_child
    hp, ht, pid, tid = _winapi.CreateProcess(executable, args,
                       ~~~~~~~~~~~~~~~~~~~~~^^^^^^^^^^^^^^^^^^
                             # no special security
                             ^^^^^^^^^^^^^^^^^^^^^
    ...<4 lines>...
                             cwd,
                             ^^^^
                             startupinfo)
                             ^^^^^^^^^^^^
PermissionError: [WinError 32] Процесс не может получить доступ к файлу, так как этот файл занят другим процессом

The above exception was the direct cause of the following exception:

Traceback (most recent call last):
  File "C:\Users\priva\Desktop\Zapros2\main.py", line 29, in init_driver
    driver = webdriver.Chrome(service=service, options=options)
  File "C:\Users\priva\Desktop\Zapros2\.venv\Lib\site-packages\selenium\webdriver\chrome\webdriver.py", line 45, in __init__
    super().__init__(
    ~~~~~~~~~~~~~~~~^
        browser_name=DesiredCapabilities.CHROME["browserName"],
        ^^^^^^^^^^^^^^^^^^^^^^^^^^^^^^^^^^^^^^^^^^^^^^^^^^^^^^^
    ...<3 lines>...
        keep_alive=keep_alive,
        ^^^^^^^^^^^^^^^^^^^^^^
    )
    ^
  File "C:\Users\priva\Desktop\Zapros2\.venv\Lib\site-packages\selenium\webdriver\chromium\webdriver.py", line 55, in __init__
    self.service.start()
    ~~~~~~~~~~~~~~~~~~^^
  File "C:\Users\priva\Desktop\Zapros2\.venv\Lib\site-packages\selenium\webdriver\common\service.py", line 109, in start
    self._start_process(self._path)
    ~~~~~~~~~~~~~~~~~~~^^^^^^^^^^^^
  File "C:\Users\priva\Desktop\Zapros2\.venv\Lib\site-packages\selenium\webdriver\common\service.py", line 243, in _start_process
    raise WebDriverException(
        f"'{os.path.basename(self._path)}' executable may have wrong permissions."
    ) from err
selenium.common.exceptions.WebDriverException: Message: 'chromedriver.exe' executable may have wrong permissions.

2025-04-01 19:49:51 - webdriver - INFO - WebDriver успешно инициализирован
2025-04-01 19:49:51 - webdriver - INFO - WebDriver успешно инициализирован
2025-04-01 19:49:52 - webdriver - INFO - WebDriver успешно инициализирован
2025-04-01 19:50:07 - webdriver - INFO - WebDriver успешно инициализирован
2025-04-01 19:50:07 - webdriver - INFO - WebDriver успешно инициализирован
2025-04-01 19:50:08 - webdriver - INFO - WebDriver успешно инициализирован
2025-04-01 19:50:08 - webdriver - INFO - WebDriver успешно инициализирован
2025-04-01 19:50:08 - webdriver - INFO - WebDriver успешно инициализирован
2025-04-01 19:50:08 - webdriver - INFO - WebDriver успешно инициализирован
2025-04-01 19:50:08 - webdriver - INFO - WebDriver успешно инициализирован
2025-04-01 19:50:08 - webdriver - INFO - WebDriver успешно инициализирован
2025-04-01 19:50:08 - webdriver - INFO - WebDriver успешно инициализирован
2025-04-01 19:50:08 - webdriver - INFO - WebDriver успешно инициализирован
2025-04-01 19:50:08 - webdriver - INFO - WebDriver успешно инициализирован
2025-04-01 19:50:08 - webdriver - INFO - WebDriver успешно инициализирован
